[2025-07-05T11:45:42.022+0000] {taskinstance.py:1157} INFO - Dependencies all met for dep_context=non-requeueable deps ti=<TaskInstance: weather_data_pipeline.download_and_process manual__2025-07-05T09:54:46.017043+00:00 map_index=2 [queued]>
[2025-07-05T11:45:42.232+0000] {taskinstance.py:1157} INFO - Dependencies all met for dep_context=requeueable deps ti=<TaskInstance: weather_data_pipeline.download_and_process manual__2025-07-05T09:54:46.017043+00:00 map_index=2 [queued]>
[2025-07-05T11:45:42.233+0000] {taskinstance.py:1359} INFO - Starting attempt 4 of 2
[2025-07-05T11:45:42.528+0000] {taskinstance.py:1380} INFO - Executing <Mapped(_PythonDecoratedOperator): download_and_process> on 2025-07-05 09:54:46.017043+00:00
[2025-07-05T11:45:42.533+0000] {standard_task_runner.py:57} INFO - Started process 270 to run task
[2025-07-05T11:45:42.729+0000] {standard_task_runner.py:84} INFO - Running: ['***', 'tasks', 'run', 'weather_data_pipeline', 'download_and_process', 'manual__2025-07-05T09:54:46.017043+00:00', '--job-id', '138', '--raw', '--subdir', 'DAGS_FOLDER/weather_data_pipeline.py', '--cfg-path', '/tmp/tmph6ndg97s', '--map-index', '2']
[2025-07-05T11:45:42.735+0000] {standard_task_runner.py:85} INFO - Job 138: Subtask download_and_process
[2025-07-05T11:45:43.235+0000] {logging_mixin.py:151} WARNING - /home/***/.local/lib/python3.8/site-packages/***/settings.py:195 DeprecationWarning: The sql_alchemy_conn option in [core] has been moved to the sql_alchemy_conn option in [database] - the old setting has been used, but please update your config.
[2025-07-05T11:45:43.639+0000] {task_command.py:415} INFO - Running <TaskInstance: weather_data_pipeline.download_and_process manual__2025-07-05T09:54:46.017043+00:00 map_index=2 [running]> on host 63adaf3f7c0d
[2025-07-05T11:46:07.027+0000] {taskinstance.py:1660} INFO - Exporting env vars: AIRFLOW_CTX_DAG_OWNER='***' AIRFLOW_CTX_DAG_ID='weather_data_pipeline' AIRFLOW_CTX_TASK_ID='download_and_process' AIRFLOW_CTX_EXECUTION_DATE='2025-07-05T09:54:46.017043+00:00' AIRFLOW_CTX_TRY_NUMBER='4' AIRFLOW_CTX_DAG_RUN_ID='manual__2025-07-05T09:54:46.017043+00:00'
[2025-07-05T11:46:07.035+0000] {logging_mixin.py:151} INFO - Starting download of 2022.csv.gz
[2025-07-05T11:46:07.137+0000] {base.py:73} INFO - Using connection ID 'noaa_http' for task execution.
[2025-07-05T11:46:07.137+0000] {logging_mixin.py:151} INFO - Downloading from: https://www.ncei.noaa.gov/pub/data/ghcn/daily/by_year/2022.csv.gz
[2025-07-05T11:46:07.223+0000] {base.py:73} INFO - Using connection ID 'noaa_http' for task execution.
[2025-07-05T11:46:12.824+0000] {local_task_job_runner.py:294} WARNING - State of this instance has been externally set to restarting. Terminating instance.
[2025-07-05T11:46:13.224+0000] {process_utils.py:131} INFO - Sending 15 to group 270. PIDs of all processes in the group: [270]
[2025-07-05T11:46:13.227+0000] {process_utils.py:86} INFO - Sending the signal 15 to group 270
[2025-07-05T11:46:13.228+0000] {taskinstance.py:1630} ERROR - Received SIGTERM. Terminating subprocesses.
[2025-07-05T11:46:13.233+0000] {logging_mixin.py:151} INFO - Error downloading 2022.csv.gz: Task received SIGTERM signal
[2025-07-05T11:46:13.918+0000] {taskinstance.py:1935} ERROR - Task failed with exception
Traceback (most recent call last):
  File "/home/airflow/.local/lib/python3.8/site-packages/airflow/decorators/base.py", line 221, in execute
    return_value = super().execute(context)
  File "/home/airflow/.local/lib/python3.8/site-packages/airflow/operators/python.py", line 192, in execute
    return_value = self.execute_callable()
  File "/home/airflow/.local/lib/python3.8/site-packages/airflow/operators/python.py", line 209, in execute_callable
    return self.python_callable(*self.op_args, **self.op_kwargs)
  File "/opt/airflow/dags/weather_data_pipeline.py", line 75, in download_and_process
    r = hook.run('/pub/data/ghcn/daily/by_year/' + file_name,
  File "/home/airflow/.local/lib/python3.8/site-packages/airflow/providers/http/hooks/http.py", line 166, in run
    return self.run_and_check(session, prepped_request, extra_options)
  File "/home/airflow/.local/lib/python3.8/site-packages/airflow/providers/http/hooks/http.py", line 214, in run_and_check
    response = session.send(prepped_request, **send_kwargs)
  File "/home/airflow/.local/lib/python3.8/site-packages/requests/sessions.py", line 747, in send
    r.content
  File "/home/airflow/.local/lib/python3.8/site-packages/requests/models.py", line 899, in content
    self._content = b"".join(self.iter_content(CONTENT_CHUNK_SIZE)) or b""
  File "/home/airflow/.local/lib/python3.8/site-packages/requests/models.py", line 816, in generate
    yield from self.raw.stream(chunk_size, decode_content=True)
  File "/home/airflow/.local/lib/python3.8/site-packages/urllib3/response.py", line 628, in stream
    data = self.read(amt=amt, decode_content=decode_content)
  File "/home/airflow/.local/lib/python3.8/site-packages/urllib3/response.py", line 567, in read
    data = self._fp_read(amt) if not fp_closed else b""
  File "/home/airflow/.local/lib/python3.8/site-packages/urllib3/response.py", line 533, in _fp_read
    return self._fp.read(amt) if amt is not None else self._fp.read()
  File "/usr/local/lib/python3.8/http/client.py", line 459, in read
    n = self.readinto(b)
  File "/usr/local/lib/python3.8/http/client.py", line 503, in readinto
    n = self.fp.readinto(b)
  File "/usr/local/lib/python3.8/socket.py", line 669, in readinto
    return self._sock.recv_into(b)
  File "/usr/local/lib/python3.8/ssl.py", line 1274, in recv_into
    return self.read(nbytes, buffer)
  File "/usr/local/lib/python3.8/ssl.py", line 1132, in read
    return self._sslobj.read(len, buffer)
  File "/home/airflow/.local/lib/python3.8/site-packages/airflow/models/taskinstance.py", line 1632, in signal_handler
    raise AirflowException("Task received SIGTERM signal")
airflow.exceptions.AirflowException: Task received SIGTERM signal
[2025-07-05T11:46:15.524+0000] {taskinstance.py:1398} INFO - Marking task as UP_FOR_RETRY. dag_id=weather_data_pipeline, task_id=download_and_process, map_index=2, execution_date=20250705T095446, start_date=20250705T114542, end_date=20250705T114614
[2025-07-05T11:46:17.530+0000] {standard_task_runner.py:104} ERROR - Failed to execute job 138 for task download_and_process (Task received SIGTERM signal; 270)
