[2025-07-06T15:42:27.453+0000] {taskinstance.py:1157} INFO - Dependencies all met for dep_context=non-requeueable deps ti=<TaskInstance: weather_data_pipeline.list_files manual__2025-07-06T15:42:26+00:00 [queued]>
[2025-07-06T15:42:27.456+0000] {taskinstance.py:1157} INFO - Dependencies all met for dep_context=requeueable deps ti=<TaskInstance: weather_data_pipeline.list_files manual__2025-07-06T15:42:26+00:00 [queued]>
[2025-07-06T15:42:27.456+0000] {taskinstance.py:1359} INFO - Starting attempt 1 of 2
[2025-07-06T15:42:27.460+0000] {taskinstance.py:1380} INFO - Executing <Task(_PythonDecoratedOperator): list_files> on 2025-07-06 15:42:26+00:00
[2025-07-06T15:42:27.463+0000] {standard_task_runner.py:57} INFO - Started process 431 to run task
[2025-07-06T15:42:27.464+0000] {standard_task_runner.py:84} INFO - Running: ['***', 'tasks', 'run', 'weather_data_pipeline', 'list_files', 'manual__2025-07-06T15:42:26+00:00', '--job-id', '8', '--raw', '--subdir', 'DAGS_FOLDER/weather_data_pipeline.py', '--cfg-path', '/tmp/tmprxrv347m']
[2025-07-06T15:42:27.465+0000] {standard_task_runner.py:85} INFO - Job 8: Subtask list_files
[2025-07-06T15:42:27.471+0000] {logging_mixin.py:151} WARNING - /home/***/.local/lib/python3.8/site-packages/***/settings.py:195 DeprecationWarning: The sql_alchemy_conn option in [core] has been moved to the sql_alchemy_conn option in [database] - the old setting has been used, but please update your config.
[2025-07-06T15:42:27.486+0000] {task_command.py:415} INFO - Running <TaskInstance: weather_data_pipeline.list_files manual__2025-07-06T15:42:26+00:00 [running]> on host 2331dcd11242
[2025-07-06T15:42:27.619+0000] {taskinstance.py:1660} INFO - Exporting env vars: AIRFLOW_CTX_DAG_OWNER='***' AIRFLOW_CTX_DAG_ID='weather_data_pipeline' AIRFLOW_CTX_TASK_ID='list_files' AIRFLOW_CTX_EXECUTION_DATE='2025-07-06T15:42:26+00:00' AIRFLOW_CTX_TRY_NUMBER='1' AIRFLOW_CTX_DAG_RUN_ID='manual__2025-07-06T15:42:26+00:00'
[2025-07-06T15:42:27.622+0000] {base.py:73} INFO - Using connection ID 'noaa_http' for task execution.
[2025-07-06T15:42:27.626+0000] {http.py:221} WARNING - HTTPSConnectionPool(host='www.ncei.noaa.gov', port=443): Max retries exceeded with url: //pub/data/ghcn/daily/by_year/ (Caused by NewConnectionError('<urllib3.connection.HTTPSConnection object at 0xffff72ca9250>: Failed to establish a new connection: [Errno -2] Name or service not known')) Tenacity will retry to execute the operation
[2025-07-06T15:42:27.627+0000] {taskinstance.py:1935} ERROR - Task failed with exception
Traceback (most recent call last):
  File "/home/airflow/.local/lib/python3.8/site-packages/urllib3/connection.py", line 174, in _new_conn
    conn = connection.create_connection(
  File "/home/airflow/.local/lib/python3.8/site-packages/urllib3/util/connection.py", line 72, in create_connection
    for res in socket.getaddrinfo(host, port, family, socket.SOCK_STREAM):
  File "/usr/local/lib/python3.8/socket.py", line 918, in getaddrinfo
    for res in _socket.getaddrinfo(host, port, family, type, proto, flags):
socket.gaierror: [Errno -2] Name or service not known

During handling of the above exception, another exception occurred:

Traceback (most recent call last):
  File "/home/airflow/.local/lib/python3.8/site-packages/urllib3/connectionpool.py", line 714, in urlopen
    httplib_response = self._make_request(
  File "/home/airflow/.local/lib/python3.8/site-packages/urllib3/connectionpool.py", line 403, in _make_request
    self._validate_conn(conn)
  File "/home/airflow/.local/lib/python3.8/site-packages/urllib3/connectionpool.py", line 1053, in _validate_conn
    conn.connect()
  File "/home/airflow/.local/lib/python3.8/site-packages/urllib3/connection.py", line 363, in connect
    self.sock = conn = self._new_conn()
  File "/home/airflow/.local/lib/python3.8/site-packages/urllib3/connection.py", line 186, in _new_conn
    raise NewConnectionError(
urllib3.exceptions.NewConnectionError: <urllib3.connection.HTTPSConnection object at 0xffff72ca9250>: Failed to establish a new connection: [Errno -2] Name or service not known

During handling of the above exception, another exception occurred:

Traceback (most recent call last):
  File "/home/airflow/.local/lib/python3.8/site-packages/requests/adapters.py", line 486, in send
    resp = conn.urlopen(
  File "/home/airflow/.local/lib/python3.8/site-packages/urllib3/connectionpool.py", line 798, in urlopen
    retries = retries.increment(
  File "/home/airflow/.local/lib/python3.8/site-packages/urllib3/util/retry.py", line 592, in increment
    raise MaxRetryError(_pool, url, error or ResponseError(cause))
urllib3.exceptions.MaxRetryError: HTTPSConnectionPool(host='www.ncei.noaa.gov', port=443): Max retries exceeded with url: //pub/data/ghcn/daily/by_year/ (Caused by NewConnectionError('<urllib3.connection.HTTPSConnection object at 0xffff72ca9250>: Failed to establish a new connection: [Errno -2] Name or service not known'))

During handling of the above exception, another exception occurred:

Traceback (most recent call last):
  File "/home/airflow/.local/lib/python3.8/site-packages/airflow/decorators/base.py", line 221, in execute
    return_value = super().execute(context)
  File "/home/airflow/.local/lib/python3.8/site-packages/airflow/operators/python.py", line 192, in execute
    return_value = self.execute_callable()
  File "/home/airflow/.local/lib/python3.8/site-packages/airflow/operators/python.py", line 209, in execute_callable
    return self.python_callable(*self.op_args, **self.op_kwargs)
  File "/opt/airflow/dags/weather_data_pipeline.py", line 36, in list_files
    response = hook.run("/pub/data/ghcn/daily/by_year/")
  File "/home/airflow/.local/lib/python3.8/site-packages/airflow/providers/http/hooks/http.py", line 166, in run
    return self.run_and_check(session, prepped_request, extra_options)
  File "/home/airflow/.local/lib/python3.8/site-packages/airflow/providers/http/hooks/http.py", line 222, in run_and_check
    raise ex
  File "/home/airflow/.local/lib/python3.8/site-packages/airflow/providers/http/hooks/http.py", line 214, in run_and_check
    response = session.send(prepped_request, **send_kwargs)
  File "/home/airflow/.local/lib/python3.8/site-packages/requests/sessions.py", line 703, in send
    r = adapter.send(request, **kwargs)
  File "/home/airflow/.local/lib/python3.8/site-packages/requests/adapters.py", line 519, in send
    raise ConnectionError(e, request=request)
requests.exceptions.ConnectionError: HTTPSConnectionPool(host='www.ncei.noaa.gov', port=443): Max retries exceeded with url: //pub/data/ghcn/daily/by_year/ (Caused by NewConnectionError('<urllib3.connection.HTTPSConnection object at 0xffff72ca9250>: Failed to establish a new connection: [Errno -2] Name or service not known'))
[2025-07-06T15:42:27.631+0000] {taskinstance.py:1398} INFO - Marking task as UP_FOR_RETRY. dag_id=weather_data_pipeline, task_id=list_files, execution_date=20250706T154226, start_date=20250706T154227, end_date=20250706T154227
[2025-07-06T15:42:27.635+0000] {standard_task_runner.py:104} ERROR - Failed to execute job 8 for task list_files (HTTPSConnectionPool(host='www.ncei.noaa.gov', port=443): Max retries exceeded with url: //pub/data/ghcn/daily/by_year/ (Caused by NewConnectionError('<urllib3.connection.HTTPSConnection object at 0xffff72ca9250>: Failed to establish a new connection: [Errno -2] Name or service not known')); 431)
[2025-07-06T15:42:27.657+0000] {local_task_job_runner.py:228} INFO - Task exited with return code 1
[2025-07-06T15:42:27.667+0000] {taskinstance.py:2776} INFO - 0 downstream tasks scheduled from follow-on schedule check
