[2025-07-05T09:59:48.078+0000] {taskinstance.py:1157} INFO - Dependencies all met for dep_context=non-requeueable deps ti=<TaskInstance: weather_data_pipeline.list_files manual__2025-07-05T09:54:46.017043+00:00 [queued]>
[2025-07-05T09:59:48.081+0000] {taskinstance.py:1157} INFO - Dependencies all met for dep_context=requeueable deps ti=<TaskInstance: weather_data_pipeline.list_files manual__2025-07-05T09:54:46.017043+00:00 [queued]>
[2025-07-05T09:59:48.081+0000] {taskinstance.py:1359} INFO - Starting attempt 2 of 2
[2025-07-05T09:59:48.086+0000] {taskinstance.py:1380} INFO - Executing <Task(_PythonDecoratedOperator): list_files> on 2025-07-05 09:54:46.017043+00:00
[2025-07-05T09:59:48.088+0000] {standard_task_runner.py:57} INFO - Started process 367 to run task
[2025-07-05T09:59:48.090+0000] {standard_task_runner.py:84} INFO - Running: ['***', 'tasks', 'run', 'weather_data_pipeline', 'list_files', 'manual__2025-07-05T09:54:46.017043+00:00', '--job-id', '5', '--raw', '--subdir', 'DAGS_FOLDER/weather_data_pipeline.py', '--cfg-path', '/tmp/tmpnmmj4757']
[2025-07-05T09:59:48.091+0000] {standard_task_runner.py:85} INFO - Job 5: Subtask list_files
[2025-07-05T09:59:48.097+0000] {logging_mixin.py:151} WARNING - /home/***/.local/lib/python3.8/site-packages/***/settings.py:195 DeprecationWarning: The sql_alchemy_conn option in [core] has been moved to the sql_alchemy_conn option in [database] - the old setting has been used, but please update your config.
[2025-07-05T09:59:48.110+0000] {task_command.py:415} INFO - Running <TaskInstance: weather_data_pipeline.list_files manual__2025-07-05T09:54:46.017043+00:00 [running]> on host 50a81e38c03c
[2025-07-05T09:59:48.239+0000] {taskinstance.py:1660} INFO - Exporting env vars: AIRFLOW_CTX_DAG_OWNER='***' AIRFLOW_CTX_DAG_ID='weather_data_pipeline' AIRFLOW_CTX_TASK_ID='list_files' AIRFLOW_CTX_EXECUTION_DATE='2025-07-05T09:54:46.017043+00:00' AIRFLOW_CTX_TRY_NUMBER='2' AIRFLOW_CTX_DAG_RUN_ID='manual__2025-07-05T09:54:46.017043+00:00'
[2025-07-05T09:59:48.245+0000] {taskinstance.py:1935} ERROR - Task failed with exception
Traceback (most recent call last):
  File "/home/airflow/.local/lib/python3.8/site-packages/airflow/decorators/base.py", line 221, in execute
    return_value = super().execute(context)
  File "/home/airflow/.local/lib/python3.8/site-packages/airflow/operators/python.py", line 192, in execute
    return_value = self.execute_callable()
  File "/home/airflow/.local/lib/python3.8/site-packages/airflow/operators/python.py", line 209, in execute_callable
    return self.python_callable(*self.op_args, **self.op_kwargs)
  File "/opt/airflow/dags/weather_data_pipeline.py", line 35, in list_files
    response = hook.run("")
  File "/home/airflow/.local/lib/python3.8/site-packages/airflow/providers/http/hooks/http.py", line 145, in run
    session = self.get_conn(headers)
  File "/home/airflow/.local/lib/python3.8/site-packages/airflow/providers/http/hooks/http.py", line 98, in get_conn
    conn = self.get_connection(self.http_conn_id)
  File "/home/airflow/.local/lib/python3.8/site-packages/airflow/hooks/base.py", line 72, in get_connection
    conn = Connection.get_connection_from_secrets(conn_id)
  File "/home/airflow/.local/lib/python3.8/site-packages/airflow/models/connection.py", line 477, in get_connection_from_secrets
    raise AirflowNotFoundException(f"The conn_id `{conn_id}` isn't defined")
airflow.exceptions.AirflowNotFoundException: The conn_id `noaa_http` isn't defined
[2025-07-05T09:59:48.247+0000] {taskinstance.py:1398} INFO - Marking task as FAILED. dag_id=weather_data_pipeline, task_id=list_files, execution_date=20250705T095446, start_date=20250705T095948, end_date=20250705T095948
[2025-07-05T09:59:48.251+0000] {standard_task_runner.py:104} ERROR - Failed to execute job 5 for task list_files (The conn_id `noaa_http` isn't defined; 367)
[2025-07-05T09:59:48.276+0000] {local_task_job_runner.py:228} INFO - Task exited with return code 1
[2025-07-05T09:59:48.286+0000] {taskinstance.py:2776} INFO - 0 downstream tasks scheduled from follow-on schedule check
