[2025-07-05T10:53:14.999+0000] {taskinstance.py:1157} INFO - Dependencies all met for dep_context=non-requeueable deps ti=<TaskInstance: weather_data_pipeline.download_and_process manual__2025-07-05T00:00:00+00:00 map_index=0 [queued]>
[2025-07-05T10:53:15.002+0000] {taskinstance.py:1157} INFO - Dependencies all met for dep_context=requeueable deps ti=<TaskInstance: weather_data_pipeline.download_and_process manual__2025-07-05T00:00:00+00:00 map_index=0 [queued]>
[2025-07-05T10:53:15.003+0000] {taskinstance.py:1359} INFO - Starting attempt 2 of 2
[2025-07-05T10:53:15.008+0000] {taskinstance.py:1380} INFO - Executing <Mapped(_PythonDecoratedOperator): download_and_process> on 2025-07-05 00:00:00+00:00
[2025-07-05T10:53:15.011+0000] {standard_task_runner.py:57} INFO - Started process 1350 to run task
[2025-07-05T10:53:15.013+0000] {standard_task_runner.py:84} INFO - Running: ['***', 'tasks', 'run', 'weather_data_pipeline', 'download_and_process', 'manual__2025-07-05T00:00:00+00:00', '--job-id', '45', '--raw', '--subdir', 'DAGS_FOLDER/weather_data_pipeline.py', '--cfg-path', '/tmp/tmpz27gel4a', '--map-index', '0']
[2025-07-05T10:53:15.015+0000] {standard_task_runner.py:85} INFO - Job 45: Subtask download_and_process
[2025-07-05T10:53:15.022+0000] {logging_mixin.py:151} WARNING - /home/***/.local/lib/python3.8/site-packages/***/settings.py:195 DeprecationWarning: The sql_alchemy_conn option in [core] has been moved to the sql_alchemy_conn option in [database] - the old setting has been used, but please update your config.
[2025-07-05T10:53:15.038+0000] {task_command.py:415} INFO - Running <TaskInstance: weather_data_pipeline.download_and_process manual__2025-07-05T00:00:00+00:00 map_index=0 [running]> on host 50a81e38c03c
[2025-07-05T10:53:15.164+0000] {taskinstance.py:1660} INFO - Exporting env vars: AIRFLOW_CTX_DAG_OWNER='***' AIRFLOW_CTX_DAG_ID='weather_data_pipeline' AIRFLOW_CTX_TASK_ID='download_and_process' AIRFLOW_CTX_EXECUTION_DATE='2025-07-05T00:00:00+00:00' AIRFLOW_CTX_TRY_NUMBER='2' AIRFLOW_CTX_DAG_RUN_ID='manual__2025-07-05T00:00:00+00:00'
[2025-07-05T10:53:15.165+0000] {logging_mixin.py:151} INFO - Starting download of 2020.csv.gz
[2025-07-05T10:53:15.168+0000] {base.py:73} INFO - Using connection ID 'noaa_http' for task execution.
[2025-07-05T10:56:26.446+0000] {local_task_job_runner.py:274} WARNING - Recorded pid 1428 does not match the current pid 1350
[2025-07-05T10:56:26.448+0000] {process_utils.py:131} INFO - Sending 15 to group 1350. PIDs of all processes in the group: [1350]
[2025-07-05T10:56:26.448+0000] {process_utils.py:86} INFO - Sending the signal 15 to group 1350
[2025-07-05T10:56:26.449+0000] {taskinstance.py:1630} ERROR - Received SIGTERM. Terminating subprocesses.
[2025-07-05T10:56:26.459+0000] {taskinstance.py:1935} ERROR - Task failed with exception
Traceback (most recent call last):
  File "/home/airflow/.local/lib/python3.8/site-packages/airflow/decorators/base.py", line 221, in execute
    return_value = super().execute(context)
  File "/home/airflow/.local/lib/python3.8/site-packages/airflow/operators/python.py", line 192, in execute
    return_value = self.execute_callable()
  File "/home/airflow/.local/lib/python3.8/site-packages/airflow/operators/python.py", line 209, in execute_callable
    return self.python_callable(*self.op_args, **self.op_kwargs)
  File "/opt/airflow/dags/weather_data_pipeline.py", line 60, in download_and_process
  File "/home/airflow/.local/lib/python3.8/site-packages/airflow/providers/http/hooks/http.py", line 166, in run
    return self.run_and_check(session, prepped_request, extra_options)
  File "/home/airflow/.local/lib/python3.8/site-packages/airflow/providers/http/hooks/http.py", line 214, in run_and_check
    response = session.send(prepped_request, **send_kwargs)
  File "/home/airflow/.local/lib/python3.8/site-packages/requests/sessions.py", line 747, in send
    r.content
  File "/home/airflow/.local/lib/python3.8/site-packages/requests/models.py", line 899, in content
    self._content = b"".join(self.iter_content(CONTENT_CHUNK_SIZE)) or b""
  File "/home/airflow/.local/lib/python3.8/site-packages/requests/models.py", line 816, in generate
    yield from self.raw.stream(chunk_size, decode_content=True)
  File "/home/airflow/.local/lib/python3.8/site-packages/urllib3/response.py", line 628, in stream
    data = self.read(amt=amt, decode_content=decode_content)
  File "/home/airflow/.local/lib/python3.8/site-packages/urllib3/response.py", line 567, in read
    data = self._fp_read(amt) if not fp_closed else b""
  File "/home/airflow/.local/lib/python3.8/site-packages/urllib3/response.py", line 533, in _fp_read
    return self._fp.read(amt) if amt is not None else self._fp.read()
  File "/usr/local/lib/python3.8/http/client.py", line 459, in read
    n = self.readinto(b)
  File "/usr/local/lib/python3.8/http/client.py", line 503, in readinto
    n = self.fp.readinto(b)
  File "/usr/local/lib/python3.8/socket.py", line 669, in readinto
    return self._sock.recv_into(b)
  File "/usr/local/lib/python3.8/ssl.py", line 1274, in recv_into
    return self.read(nbytes, buffer)
  File "/usr/local/lib/python3.8/ssl.py", line 1132, in read
    return self._sslobj.read(len, buffer)
  File "/home/airflow/.local/lib/python3.8/site-packages/airflow/models/taskinstance.py", line 1632, in signal_handler
    raise AirflowException("Task received SIGTERM signal")
airflow.exceptions.AirflowException: Task received SIGTERM signal
[2025-07-05T10:56:26.465+0000] {taskinstance.py:1398} INFO - Marking task as UP_FOR_RETRY. dag_id=weather_data_pipeline, task_id=download_and_process, map_index=0, execution_date=20250705T000000, start_date=20250705T105622, end_date=20250705T105626
[2025-07-05T10:56:26.471+0000] {standard_task_runner.py:104} ERROR - Failed to execute job 45 for task download_and_process ((psycopg2.errors.UniqueViolation) duplicate key value violates unique constraint "dag_run_dag_id_execution_date_key"
DETAIL:  Key (dag_id, execution_date)=(weather_data_pipeline, 2025-07-05 00:00:00+00) already exists.

[SQL: INSERT INTO dag_run (id, dag_id, queued_at, execution_date, start_date, end_date, state, run_id, creating_job_id, external_trigger, run_type, conf, data_interval_start, data_interval_end, last_scheduling_decision, dag_hash, log_template_id, updated_at) VALUES (%(id)s, %(dag_id)s, %(queued_at)s, %(execution_date)s, %(start_date)s, %(end_date)s, %(state)s, %(run_id)s, %(creating_job_id)s, %(external_trigger)s, %(run_type)s, %(conf)s, %(data_interval_start)s, %(data_interval_end)s, %(last_scheduling_decision)s, %(dag_hash)s, %(log_template_id)s, %(updated_at)s)]
[parameters: {'id': 14, 'dag_id': 'weather_data_pipeline', 'queued_at': None, 'execution_date': datetime.datetime(2025, 7, 5, 0, 0, tzinfo=Timezone('UTC')), 'start_date': datetime.datetime(2025, 7, 5, 0, 0, tzinfo=Timezone('UTC')), 'end_date': None, 'state': 'running', 'run_id': 'manual__2025-07-05T00:00:00+00:00', 'creating_job_id': None, 'external_trigger': False, 'run_type': 'manual', 'conf': <psycopg2.extensions.Binary object at 0xffff5e52e270>, 'data_interval_start': datetime.datetime(2025, 7, 5, 0, 0, tzinfo=Timezone('UTC')), 'data_interval_end': datetime.datetime(2025, 7, 5, 0, 0, tzinfo=Timezone('UTC')), 'last_scheduling_decision': datetime.datetime(2025, 7, 5, 10, 53, 14, 136475, tzinfo=Timezone('UTC')), 'dag_hash': '15603021937cfcea06b8d98fedd48a35', 'log_template_id': 2, 'updated_at': datetime.datetime(2025, 7, 5, 10, 53, 14, 138612, tzinfo=Timezone('UTC'))}]
(Background on this error at: https://sqlalche.me/e/14/gkpj); 1350)
[2025-07-05T10:56:26.508+0000] {process_utils.py:79} INFO - Process psutil.Process(pid=1350, status='terminated', exitcode=1, started='10:53:14') (1350) terminated with exit code 1
